<?xml version="1.0" encoding="UTF-8"?>
<!-- Generated by org.testng.reporters.JUnitReportReporter -->
<testsuite hostname="DESKTOP-R5D2F14" failures="2" tests="10" name="xmlFailedTC.FailedTC" time="0.134" errors="1" timestamp="2022-06-14T22:57:33 GMT-07:00" skipped="1">
  <testcase classname="xmlFailedTC.FailedTC" name="method9" time="0.002"/>
  <system-out>
    <![CDATA[Method9-Regression]]>
  </system-out>
  <testcase classname="xmlFailedTC.FailedTC" name="method3" time="0.002">
    <failure message="null" type="java.lang.AssertionError">
      <![CDATA[java.lang.AssertionError: null
at org.testng.Assert.fail(Assert.java:99)
at org.testng.Assert.fail(Assert.java:106)
at xmlFailedTC.FailedTC.method3(FailedTC.java:20)
at java.base/jdk.internal.reflect.NativeMethodAccessorImpl.invoke0(Native Method)
at java.base/jdk.internal.reflect.NativeMethodAccessorImpl.invoke(NativeMethodAccessorImpl.java:62)
at java.base/jdk.internal.reflect.DelegatingMethodAccessorImpl.invoke(DelegatingMethodAccessorImpl.java:43)
at java.base/java.lang.reflect.Method.invoke(Method.java:566)
at org.testng.internal.MethodInvocationHelper.invokeMethod(MethodInvocationHelper.java:133)
at org.testng.internal.TestInvoker.invokeMethod(TestInvoker.java:598)
at org.testng.internal.TestInvoker.invokeTestMethod(TestInvoker.java:173)
at org.testng.internal.MethodRunner.runInSequence(MethodRunner.java:46)
at org.testng.internal.TestInvoker$MethodInvocationAgent.invoke(TestInvoker.java:824)
at org.testng.internal.TestInvoker.invokeTestMethods(TestInvoker.java:146)
at org.testng.internal.TestMethodWorker.invokeTestMethods(TestMethodWorker.java:146)
at org.testng.internal.TestMethodWorker.run(TestMethodWorker.java:128)
at java.base/java.util.ArrayList.forEach(ArrayList.java:1541)
at org.testng.TestRunner.privateRun(TestRunner.java:794)
at org.testng.TestRunner.run(TestRunner.java:596)
at org.testng.SuiteRunner.runTest(SuiteRunner.java:377)
at org.testng.SuiteRunner.runSequentially(SuiteRunner.java:371)
at org.testng.SuiteRunner.privateRun(SuiteRunner.java:332)
at org.testng.SuiteRunner.run(SuiteRunner.java:276)
at org.testng.SuiteRunnerWorker.runSuite(SuiteRunnerWorker.java:53)
at org.testng.SuiteRunnerWorker.run(SuiteRunnerWorker.java:96)
at org.testng.TestNG.runSuitesSequentially(TestNG.java:1212)
at org.testng.TestNG.runSuitesLocally(TestNG.java:1134)
at org.testng.TestNG.runSuites(TestNG.java:1063)
at org.testng.TestNG.run(TestNG.java:1031)
at org.testng.remote.AbstractRemoteTestNG.run(AbstractRemoteTestNG.java:115)
at org.testng.remote.RemoteTestNG.initAndRun(RemoteTestNG.java:251)
at org.testng.remote.RemoteTestNG.main(RemoteTestNG.java:77)
]]>
    </failure>
  </testcase> <!-- method3 -->
  <system-out/>
  <testcase classname="xmlFailedTC.FailedTC" name="method5" time="0.001"/>
  <system-out>
    <![CDATA[Method5-Regression]]>
  </system-out>
  <testcase classname="xmlFailedTC.FailedTC" name="method4" time="0.001"/>
  <system-out>
    <![CDATA[Method4-Sanity]]>
  </system-out>
  <testcase classname="xmlFailedTC.FailedTC" name="method8" time="0.002"/>
  <system-out>
    <![CDATA[Method8-Sanity]]>
  </system-out>
  <testcase classname="xmlFailedTC.FailedTC" name="method7" time="0.002"/>
  <system-out>
    <![CDATA[Method7-Regression]]>
  </system-out>
  <testcase classname="xmlFailedTC.FailedTC" name="method10" time="0.005">
    <failure message="null" type="java.lang.AssertionError">
      <![CDATA[java.lang.AssertionError: null
at org.testng.Assert.fail(Assert.java:99)
at org.testng.Assert.fail(Assert.java:106)
at xmlFailedTC.FailedTC.method10(FailedTC.java:56)
at java.base/jdk.internal.reflect.NativeMethodAccessorImpl.invoke0(Native Method)
at java.base/jdk.internal.reflect.NativeMethodAccessorImpl.invoke(NativeMethodAccessorImpl.java:62)
at java.base/jdk.internal.reflect.DelegatingMethodAccessorImpl.invoke(DelegatingMethodAccessorImpl.java:43)
at java.base/java.lang.reflect.Method.invoke(Method.java:566)
at org.testng.internal.MethodInvocationHelper.invokeMethod(MethodInvocationHelper.java:133)
at org.testng.internal.TestInvoker.invokeMethod(TestInvoker.java:598)
at org.testng.internal.TestInvoker.invokeTestMethod(TestInvoker.java:173)
at org.testng.internal.MethodRunner.runInSequence(MethodRunner.java:46)
at org.testng.internal.TestInvoker$MethodInvocationAgent.invoke(TestInvoker.java:824)
at org.testng.internal.TestInvoker.invokeTestMethods(TestInvoker.java:146)
at org.testng.internal.TestMethodWorker.invokeTestMethods(TestMethodWorker.java:146)
at org.testng.internal.TestMethodWorker.run(TestMethodWorker.java:128)
at java.base/java.util.ArrayList.forEach(ArrayList.java:1541)
at org.testng.TestRunner.privateRun(TestRunner.java:794)
at org.testng.TestRunner.run(TestRunner.java:596)
at org.testng.SuiteRunner.runTest(SuiteRunner.java:377)
at org.testng.SuiteRunner.runSequentially(SuiteRunner.java:371)
at org.testng.SuiteRunner.privateRun(SuiteRunner.java:332)
at org.testng.SuiteRunner.run(SuiteRunner.java:276)
at org.testng.SuiteRunnerWorker.runSuite(SuiteRunnerWorker.java:53)
at org.testng.SuiteRunnerWorker.run(SuiteRunnerWorker.java:96)
at org.testng.TestNG.runSuitesSequentially(TestNG.java:1212)
at org.testng.TestNG.runSuitesLocally(TestNG.java:1134)
at org.testng.TestNG.runSuites(TestNG.java:1063)
at org.testng.TestNG.run(TestNG.java:1031)
at org.testng.remote.AbstractRemoteTestNG.run(AbstractRemoteTestNG.java:115)
at org.testng.remote.RemoteTestNG.initAndRun(RemoteTestNG.java:251)
at org.testng.remote.RemoteTestNG.main(RemoteTestNG.java:77)
]]>
    </failure>
  </testcase> <!-- method10 -->
  <system-out/>
  <testcase classname="xmlFailedTC.FailedTC" name="method1" time="0.118">
    <error message="Method xmlFailedTC.FailedTC.method1() didn&#039;t finish within the time-out 100" type="org.testng.internal.thread.ThreadTimeoutException">
      <![CDATA[org.testng.internal.thread.ThreadTimeoutException: Method xmlFailedTC.FailedTC.method1() didn't finish within the time-out 100
at org.testng.internal.MethodInvocationHelper.invokeWithTimeoutWithNewExecutor(MethodInvocationHelper.java:384)
at org.testng.internal.MethodInvocationHelper.invokeWithTimeout(MethodInvocationHelper.java:283)
at org.testng.internal.TestInvoker.invokeMethod(TestInvoker.java:604)
at org.testng.internal.TestInvoker.invokeTestMethod(TestInvoker.java:173)
at org.testng.internal.MethodRunner.runInSequence(MethodRunner.java:46)
at org.testng.internal.TestInvoker$MethodInvocationAgent.invoke(TestInvoker.java:824)
at org.testng.internal.TestInvoker.invokeTestMethods(TestInvoker.java:146)
at org.testng.internal.TestMethodWorker.invokeTestMethods(TestMethodWorker.java:146)
at org.testng.internal.TestMethodWorker.run(TestMethodWorker.java:128)
at java.base/java.util.ArrayList.forEach(ArrayList.java:1541)
at org.testng.TestRunner.privateRun(TestRunner.java:794)
at org.testng.TestRunner.run(TestRunner.java:596)
at org.testng.SuiteRunner.runTest(SuiteRunner.java:377)
at org.testng.SuiteRunner.runSequentially(SuiteRunner.java:371)
at org.testng.SuiteRunner.privateRun(SuiteRunner.java:332)
at org.testng.SuiteRunner.run(SuiteRunner.java:276)
at org.testng.SuiteRunnerWorker.runSuite(SuiteRunnerWorker.java:53)
at org.testng.SuiteRunnerWorker.run(SuiteRunnerWorker.java:96)
at org.testng.TestNG.runSuitesSequentially(TestNG.java:1212)
at org.testng.TestNG.runSuitesLocally(TestNG.java:1134)
at org.testng.TestNG.runSuites(TestNG.java:1063)
at org.testng.TestNG.run(TestNG.java:1031)
at org.testng.remote.AbstractRemoteTestNG.run(AbstractRemoteTestNG.java:115)
at org.testng.remote.RemoteTestNG.initAndRun(RemoteTestNG.java:251)
at org.testng.remote.RemoteTestNG.main(RemoteTestNG.java:77)
]]>
    </error>
  </testcase> <!-- method1 -->
  <system-out/>
  <testcase classname="xmlFailedTC.FailedTC" name="method2" time="0.001"/>
  <system-out>
    <![CDATA[Method2-Sanity]]>
  </system-out>
  <testcase classname="xmlFailedTC.FailedTC" name="method6">
    <skipped/>
  </testcase> <!-- method6 -->
  <system-out/>
</testsuite> <!-- xmlFailedTC.FailedTC -->
